Traceback (most recent call last):
  File "/srv/conda/envs/notebook/lib/python3.9/site-packages/jupyter_cache/executors/utils.py", line 51, in single_nb_execution
    executenb(
  File "/srv/conda/envs/notebook/lib/python3.9/site-packages/nbclient/client.py", line 1093, in execute
    return NotebookClient(nb=nb, resources=resources, km=km, **kwargs).execute()
  File "/srv/conda/envs/notebook/lib/python3.9/site-packages/nbclient/util.py", line 84, in wrapped
    return just_run(coro(*args, **kwargs))
  File "/srv/conda/envs/notebook/lib/python3.9/site-packages/nbclient/util.py", line 62, in just_run
    return loop.run_until_complete(coro)
  File "/srv/conda/envs/notebook/lib/python3.9/asyncio/base_events.py", line 642, in run_until_complete
    return future.result()
  File "/srv/conda/envs/notebook/lib/python3.9/site-packages/nbclient/client.py", line 559, in async_execute
    await self.async_execute_cell(
  File "/srv/conda/envs/notebook/lib/python3.9/site-packages/nbclient/client.py", line 854, in async_execute_cell
    self._check_raise_for_error(cell, exec_reply)
  File "/srv/conda/envs/notebook/lib/python3.9/site-packages/nbclient/client.py", line 756, in _check_raise_for_error
    raise CellExecutionError.from_cell_and_msg(cell, exec_reply_content)
nbclient.exceptions.CellExecutionError: An error occurred while executing the following cell:
------------------
# both H1 and L1 will have the same time vector, so:
time = time_H1
# the time sample interval (uniformly sampled!)
dt = time[1] - time[0]

# Let's look at the data and print out some stuff:

print('time_H1: len, min, mean, max = ', \
    len(time_H1), time_H1.min(), time_H1.mean(), time_H1.max() )
print('strain_H1: len, min, mean, max = ', \
    len(strain_H1), strain_H1.min(),strain_H1.mean(),strain_H1.max())
print( 'strain_L1: len, min, mean, max = ', \
    len(strain_L1), strain_L1.min(),strain_L1.mean(),strain_L1.max())

#What's in chan_dict?  (See also https://losc.ligo.org/tutorials/)
bits = chan_dict_H1['DATA']
print("For H1, {0} out of {1} seconds contain usable DATA".format(bits.sum(), len(bits)))
bits = chan_dict_L1['DATA']
print("For L1, {0} out of {1} seconds contain usable DATA".format(bits.sum(), len(bits)))
 
------------------

[0;31m---------------------------------------------------------------------------[0m
[0;31mNameError[0m                                 Traceback (most recent call last)
Input [0;32mIn [6][0m, in [0;36m<module>[0;34m[0m
[1;32m      1[0m [38;5;66;03m# both H1 and L1 will have the same time vector, so:[39;00m
[0;32m----> 2[0m time [38;5;241m=[39m [43mtime_H1[49m
[1;32m      3[0m [38;5;66;03m# the time sample interval (uniformly sampled!)[39;00m
[1;32m      4[0m dt [38;5;241m=[39m time[[38;5;241m1[39m] [38;5;241m-[39m time[[38;5;241m0[39m]

[0;31mNameError[0m: name 'time_H1' is not defined
NameError: name 'time_H1' is not defined

